Make datasource with exp=xcsx47519:run=24:smd
Make datasource with exp=xcsx47519:run=24:smd
Make datasource with exp=xcsx47519:run=24:smd
Make datasource with exp=xcsx47519:run=24:smd
Make datasource with exp=xcsx47519:run=24:smd
Make datasource with exp=xcsx47519:run=24:smd
Make datasource with exp=xcsx47519:run=24:smd
Make datasource with exp=xcsx47519:run=24:smd
Make datasource with exp=xcsx47519:run=24:smd
Make datasource with exp=xcsx47519:run=24:smd
Will save small data to /reg/d/psdm/xcs/xcsx47519/scratch/run24_jt_cal.h5
Gathering small data for exp: xcsx47519, run: 24, events: 1000
Detectors Available: [('NoDetector.0:Evr.0', 'evr0', ''), ('EBeam', '', ''), ('FEEGasDetEnergy', '', ''), ('XCS-IPM-mono', '', ''), ('XCS-DIO-mono', '', ''), ('XCS-IPM-gon', '', ''), ('HX2-SB1-BMMON', '', ''), ('XCS-USB-ENCODER-01', '', ''), ('XCS-SB1-BMMON', '', ''), ('XCS-SB2-BMMON', '', ''), ('XcsEndstation.0:Epix100a.1', 'epix_1', ''), ('XcsEndstation.0:Epix100a.2', 'epix_2', ''), ('XcsEndstation.0:Epix10ka2M.0', 'epix10k2M', ''), ('XcsEndstation.1:Opal1000.1', 'opal_1', ''), ('ControlData', '', '')]
Saved Small Data, Processing...
New threshold: i0_med/2
Results: {'i0_low': 770.375, 'i0_high': 2551.4375, 'i0_median': 1699.625, 'int_low': 261.2944, 'int_high': 261.3144, 'int_median': 261.2944, 'peak_bin': 20, 'delta_bin': 3, 'mean_ratio': 0.15426636410999756, 'med_ratio': 0.1570718066741678, 'std_ratio': 0.011355311472994588, 'jet_location_mean': 193.0, 'jet_location_std': 0.0, 'jet_peak_mean': 656986.2, 'jet_peak_std': 14588.365}
Saved calibration to /reg/d/psdm/xcs/xcsx47519/calib/jt_results//jt_cal_24_results
Traceback (most recent call last):
  File "/cds/group/pcds/epics-dev/espov/jet_tracking/jet_tracking/jet_tracking_cal/jt_cal.py", line 533, in <module>
    with open(res_file, 'w') as f:
PermissionError: [Errno 13] Permission denied: '/cds/home/opr/xcsopr/experiments/xcsx47519/jt_calib/jt_cal_24_results'

During handling of the above exception, another exception occurred:

Traceback (most recent call last):
  File "/cds/group/pcds/epics-dev/espov/jet_tracking/jet_tracking/jet_tracking_cal/jt_cal.py", line 538, in <module>
    logger.warning('Unable to write to {}opr experiment directory: {}'.format(hutch, e))
IndexError: tuple index out of range
Closing remaining open files:/reg/d/psdm/xcs/xcsx47519/scratch/run24_jt_cal.h5...done
--------------------------------------------------------------------------
Primary job  terminated normally, but 1 process returned
a non-zero exit code. Per user-direction, the job has been aborted.
--------------------------------------------------------------------------
--------------------------------------------------------------------------
mpirun detected that one or more processes exited with non-zero status, thus causing
the job to be terminated. The first process to do so was:

  Process name: [[1256,1],0]
  Exit code:    1
--------------------------------------------------------------------------
